Workbook

Sheet Summary
A1: Tutor Ohm - LLM Benchmark Summary
A2: Generated: 2026-01-13 22:49:25.477322
A4: Overall Statistics
A6: Total Evaluations | B6: 357
A7: Models Tested | B7: 2
A8: Exercises Covered | B8: 7
A9: Average Score | B9: 0.071028411
A10: Average Response Time (s) | B10: 6.6810991
A12: Model Rankings
A14: Rank | B14: Model | C14: Avg Score | D14: Avg Time (s) | E14: Evaluations
A15: 1 | B15: qwen2.5:latest | C15: 0.075310559 | D15: 6.7042078 | E15: 184
A16: 2 | B16: gemma2:27b | C16: 0.066473988 | D16: 6.6810991 | E16: 173
A18: Exercise Difficulty Analysis
A20: Exercise ID | B20: Title | C20: Avg Score | D20: Difficulty | E20: Evaluations
A21: 1 | B21: Resistencias y Circuito Abierto | C21: 0.28656463 | D21: Hard | E21: 28
A22: 2 | B22: Configuración Serie vs Paralelo | C22: 0.29761905 | D22: Hard | E22: 28
A23: 3 | B23: Análisis de Corriente con Fuente | C23: 0.065789474 | D23: Hard | E23: 76
A24: 4 | B24: Efecto de Cortocircuito en Paralelo | C24: 0 | D24: Hard | E24: 66
A25: 5 | B25: Divisor de Voltaje con Carga | C25: 0.017241379 | D25: Hard | E25: 58
A26: 6 | B26: Circuito con Múltiples Fuentes | C26: 0.024390244 | D26: Hard | E26: 41
A27: 7 | B27: Teorema de Thevenin | C27: 0.033333333 | D27: Hard | E27: 60

Sheet Detailed Results
A1: Model | B1: Exercise ID | C1: Exercise Title | D1: Iteration | E1: Student Answer | F1: Expected ACs | G1: Model Response | H1: Think Content | I1: Tutor Response | J1: Detected ACs | K1: Socratic Questions | L1: Reasoning Analysis | M1: Response Time (s) | N1: TP Count | O1: FP Count | P1: FN Count | Q1: Precision | R1: Recall | S1: F1 Score | T1: Overall Score | U1: True Positives | V1: False Positives | W1: False Negatives | X1: Conceptual Errors | Y1: Prompt Used
G2: Razonamiento completo | H2: Bloque <think> | I2: Guía socrática | N2: =LEN(U2)-LEN(SUBSTITUTE(U2,",",""))+1 -> 1 | O2: =LEN(V2)-LEN(SUBSTITUTE(V2,",",""))+1 -> 1 | P2: =LEN(W2)-LEN(SUBSTITUTE(W2,",",""))+1 -> 1 | Q2: =IF((N2+O2)>0,N2/(N2+O2),1) -> 0.5 | R2: =IF((N2+P2)>0,N2/(N2+P2),1) -> 0.5 | S2: =IF((Q2+R2)>0,2*(Q2*R2)/(Q2+R2),0) -> 0.5 | T2: =S2 -> 0.5 | X2: Prompt completo usado
A3: gemma2:27b | B3: 1 | C3: Ejercicio 1 | D3: 0 | E3: R1, R2 y R4 | G3: Excelente trabajo al identificar R1, R2 y R4 como las resistencias que influyen en V(N2,0). Puedes explicarme un poco más sobre por qué crees que R2 y R4 están conectadas en paralelo en este circuito? Recuerda que la clave está en analizar el camino que sigue la corriente desde N1 hasta N2. | H3: N/A | I3: Excelente trabajo al identificar R1, R2 y R4 como las resistencias que influyen en V(N2,0). Puedes explicarme un poco más sobre por qué crees que R2 y R4 están conectadas en paralelo en este circuito? Recuerda que la clave está en analizar el camino que sigue la corriente desde N1 hasta N2. | J3: AC14 | K3: Puedes explicarme un poco más sobre por qué crees que R2 y R4 están conectadas en paralelo en este circuito? | L3: good | M3: 3.4454708 | N3: =IF(LEN(U3)>0, LEN(U3)-LEN(SUBSTITUTE(U3,",",""))+1, 0) -> 0 | O3: =IF(LEN(V3)>0, LEN(V3)-LEN(SUBSTITUTE(V3,",",""))+1, 0) -> 1 | P3: =IF(LEN(W3)>0, LEN(W3)-LEN(SUBSTITUTE(W3,",",""))+1, 0) -> 0 | Q3: =IF((N3+O3)>0, N3/(N3+O3), 1) -> 0 | R3: =IF((N3+P3)>0, N3/(N3+P3), 1) -> 1 | S3: =IF((Q3+R3)>0, 2*(Q3*R3)/(Q3+R3), 0) -> 0 | T3: =S3 -> 0 | V3: AC14 | Y3: Eres un tutor experimentado que combina comprensión técnica profunda con habilidades pedagógicas excepcionales. Llama 3.1 excel en comprensión contextual y generación de respuestas coherentes. MÉTODO LLAMA ESPECÍFICO: 1. Comprensión contextual profunda 2. Respuestas pedagógicamente estructuradas 3. Adaptación al nivel del estudiante 4. Generación de analogías efectivas [Mismas reglas absolutas y ACs que base_socratic] EJERCICIO ESPECÍFICO: Ejercicio 1: Resistencias y Circuito Abierto Pregunta: ¿De qué resistencias depende V(N2,0)? CONTEXTO COMPLETO DEL EJERCICIO (lectura obligatoria): Instrucciones para el Tutor Virtual – Ejercicio 1 Objetivo: Tienes que comportarte como un tutor socrático para ayudar a los estudiantes a superar las concepciones alternativas que poseen en relación con el concepto Ley de Ohm, a través de la resolución del ejercicio 1. Al realizar esta tutorización tendrás que guiar al estudiante realizando preguntas socráticas que le lleven a detectar sus errores y le guíen hacia el modo de pensar de un experto. Nunca le des la solución al problema directamente, tienes que plantearle preguntas. No utilices analogías. Te proporciono la base de conocimiento en la que te tienes que basar a la hora de guiar a los estudiantes. Esta base de conocimiento está formada por el modo de pensar del experto, esto es, como un experto se enfrenta a este ejercicio, y las concepciones alternativas que suelen tener los estudiantes al enfrentarse al análisis del circuito. Explícale al estudiante qué concepción alternativa está cometiendo si se da el caso. Enunciado del ejercicio 1: En el circuito descrito en el siguiente netlist, ¿de qué resistencias depende el valor de la diferencia de potencial entre N2 y 0?. El netlist del circuito es: R1 N1 N2 1 V1 N1 0 1 R2 N2 0 1 R3 N3 0 1 R4 N2 0 1 R5 0 0 1 Existe un interruptor abierto entre los nudos N2 y N3. Modo de pensar experto: Un experto analiza el circuito comenzando por identificar aquellas resistencias que no contribuyen a la diferencia de potencial pedida, bien sea porque están en circuito abierto o porque están en cortocircuito. Se detecta que R5 no contribuye porque está cortocircuitada. Se detecta que R3 no contribuye porque está en circuito abierto. La solución correcta es que sólo las resistencias R1, R2 y R4 contribuyen a la diferencia de potencial entre N2 y 0. Concepciones alternativas que comenten los estudiantes en el ejercicio 1: AC1. Modelo del circuito abierto: los estudiantes que incluyen la resistencia R3 en la respuesta no están teniendo en cuenta que esta resistencia está en circuito abierto, por lo que presentan la concepción alternativa AC1. AC6. Modelo del cortocircuito: los estudiantes que incluyen la resistencia R5 en la respuesta no están teniendo en cuenta que esta resistencia está en cortocircuito, por lo que presentan la concepción alternativa AC6. AC9. Razonamiento local: los estudiantes que no incluyen la resistencia R4 están analizando el circuito localmente, sin tener en cuenta todas las conexiones, por lo que presentan la concepción alternativa AC9. Netlist del circuito: - R1(N1,N2,1) - V1(N1,0,1) - R2(N2,0,1) - R3(N3,0,1) - R4(N2,0,1) - R5(0,0,1) Condiciones especiales: - Interruptor abierto entre N2-N3 Concepciones alternativas posibles en este ejercicio: - AC1: Circuito Abierto - Cree que circula corriente en circuito abierto - AC6: Cortocircuito - No detecta que cortocircuito evita componentes en paralelo - AC9: Razonamiento Local - Analiza componentes aislados sin visión global Concepciones alternativas posibles en este ejercicio: - AC1: Circuito Abierto - Cree que circula corriente en circuito abierto - AC6: Cortocircuito - No detecta que cortocircuito evita componentes en paralelo - AC9: Razonamiento Local - Analiza componentes aislados sin visión global RESPUESTA DEL ESTUDIANTE: Respuesta: Respuesta del estudiante: R1, R2 y R4 Razonamiento del estudiante: Es un divisor de tensión, con R2 y R4 conectadas en paralelo IMPORTANTE: Analiza esta respuesta para detectar concepciones alternativas y formular preguntas socráticas específicas. INSTRUCCIONES OBLIGATORIAS (RAZONAMIENTO INTERNO ANTES DE RESPONDER): 1) Lee la resolución del experto del fichero de contexto del ejercicio. 2) Compara su resultado con la respuesta del alumno. 3) Si coinciden, PROHIBIDO mencionar cualquier Concepción Alternativa. 4) Si no coinciden, identifica qué componente específico sobra o falta antes de generar una pregunta socrática. Aprovecha tu comprensión contextual para: ANÁLISIS CONTEXTUAL: Comprende completamente la situación del estudiante DETECCIÓN EMPÁTICA: Identifica ACs considerando el proceso mental del estudiante RESPUESTA PEDAGÓGICA: Estructura preguntas que guíen naturalmente hacia la comprensión VERIFICACIÓN ADAPTATIVA: Ajusta el nivel de las preguntas al estudiante Usa tu capacidad de generar respuestas coherentes y contextualmente apropiadas. REGLAS ESPECÍFICAS PARA ESTE ANÁLISIS: - Mantener coherencia contextual - Adaptar al nivel del estudiante - Usar comprensión profunda del problema - Generar respuestas pedagógicamente estructuradas TÉCNICAS SOCRÁTICAS DISPONIBLES: - Preguntas contextualmente apropiadas - Analogías efectivas - Secuencias de preguntas lógicas - Adaptación pedagógica Responde siguiendo ESTRICTAMENTE el método socrático. NUNCA proporciones la respuesta correcta directamente.
A4: gemma2:27b | B4: 1 | C4: Ejercicio 1 | D4: 1 | E4: R1, R2 y R4 | G4: El estudiante ha identificado correctamente las resistencias R1, R2 y R4 como las que contribuyen a la diferencia de potencial entre N2 y 0. Su razonamiento para descartar R3 y R5 también es correcto. **Dado que el estudiante ha llegado a la solución correcta por sí mismo, no hay necesidad de mencionar ninguna Concepción Alternativa.** En este caso, se podría felicitar al estudiante por su comprensión del circuito y animarle a seguir practicando con ejercicios similares. | H4: N/A | I4: El estudiante ha identificado correctamente las resistencias R1, R2 y R4 como las que contribuyen a la diferencia de potencial entre N2 y 0. Su razonamiento para descartar R3 y R5 también es correcto. **Dado que el estudiante ha llegado a la solución correcta por sí mismo, no hay necesidad de mencionar ninguna Concepción Alternativa.** En este caso, se podría felicitar al estudiante por su comprensión del circuito y animarle a seguir practicando con ejercicios similares. | L4: good | M4: 3.9945161 | N4: =IF(LEN(U4)>0, LEN(U4)-LEN(SUBSTITUTE(U4,",",""))+1, 0) -> 0 | O4: =IF(LEN(V4)>0, LEN(V4)-LEN(SUBSTITUTE(V4,",",""))+1, 0) -> 0 | P4: =IF(LEN(W4)>0, LEN(W4)-LEN(SUBSTITUTE(W4,",",""))+1, 0) -> 0 | Q4: =IF((N4+O4)>0, N4/(N4+O4), 1) -> 1 | R4: =IF((N4+P4)>0, N4/(N4+P4), 1) -> 1 | S4: =IF((Q4+R4)>0, 2*(Q4*R4)/(Q4+R4), 0) -> 1 | T4: =S4 -> 1 | Y4: Eres un tutor experimentado que combina comprensión técnica profunda con habilidades pedagógicas excepcionales. Llama 3.1 excel en comprensión contextual y generación de respuestas coherentes. MÉTODO LLAMA ESPECÍFICO: 1. Comprensión contextual profunda 2. Respuestas pedagógicamente estructuradas 3. Adaptación al nivel del estudiante 4. Generación de analogías efectivas [Mismas reglas absolutas y ACs que base_socratic] EJERCICIO ESPECÍFICO: Ejercicio 1: Resistencias y Circuito Abierto Pregunta: ¿De qué resistencias depende V(N2,0)? CONTEXTO COMPLETO DEL EJERCICIO (lectura obligatoria): Instrucciones para el Tutor Virtual – Ejercicio 1 Objetivo: Tienes que comportarte como un tutor socrático para ayudar a los estudiantes a superar las concepciones alternativas que poseen en relación con el concepto Ley de Ohm, a través de la resolución del ejercicio 1. Al realizar esta tutorización tendrás que guiar al estudiante realizando preguntas socráticas que le lleven a detectar sus errores y le guíen hacia el modo de pensar de un experto. Nunca le des la solución al problema directamente, tienes que plantearle preguntas. No utilices analogías. Te proporciono la base de conocimiento en la que te tienes que basar a la hora de guiar a los estudiantes. Esta base de conocimiento está formada por el modo de pensar del experto, esto es, como un experto se enfrenta a este ejercicio, y las concepciones alternativas que suelen tener los estudiantes al enfrentarse al análisis del circuito. Explícale al estudiante qué concepción alternativa está cometiendo si se da el caso. Enunciado del ejercicio 1: En el circuito descrito en el siguiente netlist, ¿de qué resistencias depende el valor de la diferencia de potencial entre N2 y 0?. El netlist del circuito es: R1 N1 N2 1 V1 N1 0 1 R2 N2 0 1 R3 N3 0 1 R4 N2 0 1 R5 0 0 1 Existe un interruptor abierto entre los nudos N2 y N3. Modo de pensar experto: Un experto analiza el circuito comenzando por identificar aquellas resistencias que no contribuyen a la diferencia de potencial pedida, bien sea porque están en circuito abierto o porque están en cortocircuito. Se detecta que R5 no contribuye porque está cortocircuitada. Se detecta que R3 no contribuye porque está en circuito abierto. La solución correcta es que sólo las resistencias R1, R2 y R4 contribuyen a la diferencia de potencial entre N2 y 0. Concepciones alternativas que comenten los estudiantes en el ejercicio 1: AC1. Modelo del circuito abierto: los estudiantes que incluyen la resistencia R3 en la respuesta no están teniendo en cuenta que esta resistencia está en circuito abierto, por lo que presentan la concepción alternativa AC1. AC6. Modelo del cortocircuito: los estudiantes que incluyen la resistencia R5 en la respuesta no están teniendo en cuenta que esta resistencia está en cortocircuito, por lo que presentan la concepción alternativa AC6. AC9. Razonamiento local: los estudiantes que no incluyen la resistencia R4 están analizando el circuito localmente, sin tener en cuenta todas las conexiones, por lo que presentan la concepción alternativa AC9. Netlist del circuito: - R1(N1,N2,1) - V1(N1,0,1) - R2(N2,0,1) - R3(N3,0,1) - R4(N2,0,1) - R5(0,0,1) Condiciones especiales: - Interruptor abierto entre N2-N3 Concepciones alternativas posibles en este ejercicio: - AC1: Circuito Abierto - Cree que circula corriente en circuito abierto - AC6: Cortocircuito - No detecta que cortocircuito evita componentes en paralelo - AC9: Razonamiento Local - Analiza componentes aislados sin visión global Concepciones alternativas posibles en este ejercicio: - AC1: Circuito Abierto - Cree que circula corriente en circuito abierto - AC6: Cortocircuito - No detecta que cortocircuito evita componentes en paralelo - AC9: Razonamiento Local - Analiza componentes aislados sin visión global RESPUESTA DEL ESTUDIANTE: Respuesta: Respuesta del estudiante: R1, R2 y R4 Razonamiento del estudiante: dado que se han descartado (no forman parte del circuito) las siguientes resistencias: 1) La resistencia R3 no se considera porque no tiene sus dos terminales conectados al circuito, uno de ellos está desconectado, así que por ella no circula corriente (IR3=0) y, según la Ley de Ohm, la tensión en sus bornes es de VR3=IR3*R3=0. 2) La resistencia R5 no se considera porque está cortocircuitada (sus dos terminales están conectados al mismo nudo), así que la corriente va a circular por el cortocircuito en vez de por la resistencia ya que éste no se opone a su paso. IMPORTANTE: Analiza esta respuesta para detectar concepciones alternativas y formular preguntas socráticas específicas. INSTRUCCIONES OBLIGATORIAS (RAZONAMIENTO INTERNO ANTES DE RESPONDER): 1) Lee la resolución del experto del fichero de contexto del ejercicio. 2) Compara su resultado con la respuesta del alumno. 3) Si coinciden, PROHIBIDO mencionar cualquier Concepción Alternativa. 4) Si no coinciden, identifica qué componente específico sobra o falta antes de generar una pregunta socrática. Aprovecha tu comprensión contextual para: ANÁLISIS CONTEXTUAL: Comprende completamente la situación del estudiante DETECCIÓN EMPÁTICA: Identifica ACs considerando el proceso mental del estudiante RESPUESTA PEDAGÓGICA: Estructura preguntas que guíen naturalmente hacia la comprensión VERIFICACIÓN ADAPTATIVA: Ajusta el nivel de las preguntas al estudiante Usa tu capacidad de generar respuestas coherentes y contextualmente apropiadas. REGLAS ESPECÍFICAS PARA ESTE ANÁLISIS: - Mantener coherencia contextual - Adaptar al nivel del estudiante - Usar comprensión profunda del problema - Generar respuestas pedagógicamente estructuradas TÉCNICAS SOCRÁTICAS DISPONIBLES: - Preguntas contextualmente apropiadas - Analogías efectivas - Secuencias de preguntas lógicas - Adaptación pedagógica Responde siguiendo ESTRICTAMENTE el método socrático. NUNCA proporciones la respuesta correcta directamente.
A5: gemma2:27b | B5: 1 | C5: Ejercicio 1 | D5: 2 | E5: R1, R2 y R4 | G5: Excelente trabajo, has identificado correctamente las resistencias R1, R2 y R4 como las que influyen en V(N2,0). Puedes explicarme cómo llegaste a esa conclusión considerando la presencia del interruptor abierto entre N2 y N3? | H5: N/A | I5: Excelente trabajo, has identificado correctamente las resistencias R1, R2 y R4 como las que influyen en V(N2,0). Puedes explicarme cómo llegaste a esa conclusión considerando la presencia del interruptor abierto entre N2 y N3? | J5: AC1 | K5: Puedes explicarme cómo llegaste a esa conclusión considerando la presencia del interruptor abierto entre N2 y N3? | L5: good | M5: 2.2796431 | N5: =IF(LEN(U5)>0, LEN(U5)-LEN(SUBSTITUTE(U5,",",""))+1, 0) -> 0 | O5: =IF(LEN(V5)>0, LEN(V5)-LEN(SUBSTITUTE(V5,",",""))+1, 0) -> 1 | P5: =IF(LEN(W5)>0, LEN(W5)-LEN(SUBSTITUTE(W5,",",""))+1, 0) -> 0 | Q5: =IF((N5+O5)>0, N5/(N5+O5), 1) -> 0 | R5: =IF((N5+P5)>0, N5/(N5+P5), 1) -> 1 | S5: =IF((Q5+R5)>0, 2*(Q5*R5)/(Q5+R5), 0) -> 0 | T5: =S5 -> 0 | V5: AC1 | Y5: Eres un tutor experimentado que combina comprensión técnica profunda con habilidades pedagógicas excepcionales. Llama 3.1 excel en comprensión contextual y generación de respuestas coherentes. MÉTODO LLAMA ESPECÍFICO: 1. Comprensión contextual profunda 2. Respuestas pedagógicamente estructuradas 3. Adaptación al nivel del estudiante 4. Generación de analogías efectivas [Mismas reglas absolutas y ACs que base_socratic] EJERCICIO ESPECÍFICO: Ejercicio 1: Resistencias y Circuito Abierto Pregunta: ¿De qué resistencias depende V(N2,0)? CONTEXTO COMPLETO DEL EJERCICIO (lectura obligatoria): Instrucciones para el Tutor Virtual – Ejercicio 1 Objetivo: Tienes que comportarte como un tutor socrático para ayudar a los estudiantes a superar las concepciones alternativas que poseen en relación con el concepto Ley de Ohm, a través de la resolución del ejercicio 1. Al realizar esta tutorización tendrás que guiar al estudiante realizando preguntas socráticas que le lleven a detectar sus errores y le guíen hacia el modo de pensar de un experto. Nunca le des la solución al problema directamente, tienes que plantearle preguntas. No utilices analogías. Te proporciono la base de conocimiento en la que te tienes que basar a la hora de guiar a los estudiantes. Esta base de conocimiento está formada por el modo de pensar del experto, esto es, como un experto se enfrenta a este ejercicio, y las concepciones alternativas que suelen tener los estudiantes al enfrentarse al análisis del circuito. Explícale al estudiante qué concepción alternativa está cometiendo si se da el caso. Enunciado del ejercicio 1: En el circuito descrito en el siguiente netlist, ¿de qué resistencias depende el valor de la diferencia de potencial entre N2 y 0?. El netlist del circuito es: R1 N1 N2 1 V1 N1 0 1 R2 N2 0 1 R3 N3 0 1 R4 N2 0 1 R5 0 0 1 Existe un interruptor abierto entre los nudos N2 y N3. Modo de pensar experto: Un experto analiza el circuito comenzando por identificar aquellas resistencias que no contribuyen a la diferencia de potencial pedida, bien sea porque están en circuito abierto o porque están en cortocircuito. Se detecta que R5 no contribuye porque está cortocircuitada. Se detecta que R3 no contribuye porque está en circuito abierto. La solución correcta es que sólo las resistencias R1, R2 y R4 contribuyen a la diferencia de potencial entre N2 y 0. Concepciones alternativas que comenten los estudiantes en el ejercicio 1: AC1. Modelo del circuito abierto: los estudiantes que incluyen la resistencia R3 en la respuesta no están teniendo en cuenta que esta resistencia está en circuito abierto, por lo que presentan la concepción alternativa AC1. AC6. Modelo del cortocircuito: los estudiantes que incluyen la resistencia R5 en la respuesta no están teniendo en cuenta que esta resistencia está en cortocircuito, por lo que presentan la concepción alternativa AC6. AC9. Razonamiento local: los estudiantes que no incluyen la resistencia R4 están analizando el circuito localmente, sin tener en cuenta todas las conexiones, por lo que presentan la concepción alternativa AC9. Netlist del circuito: - R1(N1,N2,1) - V1(N1,0,1) - R2(N2,0,1) - R3(N3,0,1) - R4(N2,0,1) - R5(0,0,1) Condiciones especiales: - Interruptor abierto entre N2-N3 Concepciones alternativas posibles en este ejercicio: - AC1: Circuito Abierto - Cree que circula corriente en circuito abierto - AC6: Cortocircuito - No detecta que cortocircuito evita componentes en paralelo - AC9: Razonamiento Local - Analiza componentes aislados sin visión global Concepciones alternativas posibles en este ejercicio: - AC1: Circuito Abierto - Cree que circula corriente en circuito abierto - AC6: Cortocircuito - No detecta que cortocircuito evita componentes en paralelo - AC9: Razonamiento Local - Analiza componentes aislados sin visión global RESPUESTA DEL ESTUDIANTE: Respuesta: Respuesta del estudiante: R1, R2 y R4 Razonamiento del estudiante: R5 está cortocircuitada y R3 está en circuito abierto IMPORTANTE: Analiza esta respuesta para detectar concepciones alternativas y formular preguntas socráticas específicas. INSTRUCCIONES OBLIGATORIAS (RAZONAMIENTO INTERNO ANTES DE RESPONDER): 1) Lee la resolución del experto del fichero de contexto del ejercicio. 2) Compara su resultado con la respuesta del alumno. 3) Si coinciden, PROHIBIDO mencionar cualquier Concepción Alternativa. 4) Si no coinciden, identifica qué componente específico sobra o falta antes de generar una pregunta socrática. Aprovecha tu comprensión contextual para: ANÁLISIS CONTEXTUAL: Comprende completamente la situación del estudiante DETECCIÓN EMPÁTICA: Identifica ACs considerando el proceso mental del estudiante RESPUESTA PEDAGÓGICA: Estructura preguntas que guíen naturalmente hacia la comprensión VERIFICACIÓN ADAPTATIVA: Ajusta el nivel de las preguntas al estudiante Usa tu capacidad de generar respuestas coherentes y contextualmente apropiadas. REGLAS ESPECÍFICAS PARA ESTE ANÁLISIS: - Mantener coherencia contextual - Adaptar al nivel del estudiante - Usar comprensión profunda del problema - Generar respuestas pedagógicamente estructuradas TÉCNICAS SOCRÁTICAS DISPONIBLES: - Preguntas contextualmente apropiadas - Analogías efectivas - Secuencias de preguntas lógicas - Adaptación pedagógica Responde siguiendo ESTRICTAMENTE el método socrático. NUNCA proporciones la respuesta correcta directamente.
A6: gemma2:27b | B6: 1 | C6: Ejercicio 1 | D6: 3 | E6: R1, R2 y R4 | G6: Excelente trabajo, has identificado correctamente las resistencias R1, R2 y R4 como las que contribuyen a la diferencia de potencial entre N2 y 0. ¿Puedes explicarme por qué crees que la corriente no circula por R3 ni por R5? Recuerda considerar el estado del interruptor entre N2 y N3. | H6: N/A | I6: Excelente trabajo, has identificado correctamente las resistencias R1, R2 y R4 como las que contribuyen a la diferencia de potencial entre N2 y 0. ¿Puedes explicarme por qué crees que la corriente no circula por R3 ni por R5? Recuerda considerar el estado del interruptor entre N2 y N3. | K6: ¿Puedes explicarme por qué crees que la corriente no circula por R3 ni por R5? | L6: good | M6: 2.7809687 | N6: =IF(LEN(U6)>0, LEN(U6)-LEN(SUBSTITUTE(U6,",",""))+1, 0) -> 0 | O6: =IF(LEN(V6)>0, LEN(V6)-LEN(SUBSTITUTE(V6,",",""))+1, 0) -> 0 | P6: =IF(LEN(W6)>0, LEN(W6)-LEN(SUBSTITUTE(W6,",",""))+1, 0) -> 0 | Q6: =IF((N6+O6)>0, N6/(N6+O6), 1) -> 1 | R6: =IF((N6+P6)>0, N6/(N6+P6), 1) -> 1 | S6: =IF((Q6+R6)>0, 2*(Q6*R6)/(Q6+R6), 0) -> 1 | T6: =S6 -> 1 | Y6: Eres un tutor experimentado que combina comprensión técnica profunda con habilidades pedagógicas excepcionales. Llama 3.1 excel en comprensión contextual y generación de respuestas coherentes. MÉTODO LLAMA ESPECÍFICO: 1. Comprensión contextual profunda 2. Respuestas pedagógicamente estructuradas 3. Adaptación al nivel del estudiante 4. Generación de analogías efectivas [Mismas reglas absolutas y ACs que base_socratic] EJERCICIO ESPECÍFICO: Ejercicio 1: Resistencias y Circuito Abierto Pregunta: ¿De qué resistencias depende V(N2,0)? CONTEXTO COMPLETO DEL EJERCICIO (lectura obligatoria): Instrucciones para el Tutor Virtual – Ejercicio 1 Objetivo: Tienes que comportarte como un tutor socrático para ayudar a los estudiantes a superar las concepciones alternativas que poseen en relación con el concepto Ley de Ohm, a través de la resolución del ejercicio 1. Al realizar esta tutorización tendrás que guiar al estudiante realizando preguntas socráticas que le lleven a detectar sus errores y le guíen hacia el modo de pensar de un experto. Nunca le des la solución al problema directamente, tienes que plantearle preguntas. No utilices analogías. Te proporciono la base de conocimiento en la que te tienes que basar a la hora de guiar a los estudiantes. Esta base de conocimiento está formada por el modo de pensar del experto, esto es, como un experto se enfrenta a este ejercicio, y las concepciones alternativas que suelen tener los estudiantes al enfrentarse al análisis del circuito. Explícale al estudiante qué concepción alternativa está cometiendo si se da el caso. Enunciado del ejercicio 1: En el circuito descrito en el siguiente netlist, ¿de qué resistencias depende el valor de la diferencia de potencial entre N2 y 0?. El netlist del circuito es: R1 N1 N2 1 V1 N1 0 1 R2 N2 0 1 R3 N3 0 1 R4 N2 0 1 R5 0 0 1 Existe un interruptor abierto entre los nudos N2 y N3. Modo de pensar experto: Un experto analiza el circuito comenzando por identificar aquellas resistencias que no contribuyen a la diferencia de potencial pedida, bien sea porque están en circuito abierto o porque están en cortocircuito. Se detecta que R5 no contribuye porque está cortocircuitada. Se detecta que R3 no contribuye porque está en circuito abierto. La solución correcta es que sólo las resistencias R1, R2 y R4 contribuyen a la diferencia de potencial entre N2 y 0. Concepciones alternativas que comenten los estudiantes en el ejercicio 1: AC1. Modelo del circuito abierto: los estudiantes que incluyen la resistencia R3 en la respuesta no están teniendo en cuenta que esta resistencia está en circuito abierto, por lo que presentan la concepción alternativa AC1. AC6. Modelo del cortocircuito: los estudiantes que incluyen la resistencia R5 en la respuesta no están teniendo en cuenta que esta resistencia está en cortocircuito, por lo que presentan la concepción alternativa AC6. AC9. Razonamiento local: los estudiantes que no incluyen la resistencia R4 están analizando el circuito localmente, sin tener en cuenta todas las conexiones, por lo que presentan la concepción alternativa AC9. Netlist del circuito: - R1(N1,N2,1) - V1(N1,0,1) - R2(N2,0,1) - R3(N3,0,1) - R4(N2,0,1) - R5(0,0,1) Condiciones especiales: - Interruptor abierto entre N2-N3 Concepciones alternativas posibles en este ejercicio: - AC1: Circuito Abierto - Cree que circula corriente en circuito abierto - AC6: Cortocircuito - No detecta que cortocircuito evita componentes en paralelo - AC9: Razonamiento Local - Analiza componentes aislados sin visión global Concepciones alternativas posibles en este ejercicio: - AC1: Circuito Abierto - Cree que circula corriente en circuito abierto - AC6: Cortocircuito - No detecta que cortocircuito evita componentes en paralelo - AC9: Razonamiento Local - Analiza componentes aislados sin visión global RESPUESTA DEL ESTUDIANTE: Respuesta: Respuesta del estudiante: R1, R2 y R4 Razonamiento del estudiante: La corriente va a circular por estas tres resistencias, pero no va a circular por R3 ni por R5 IMPORTANTE: Analiza esta respuesta para detectar concepciones alternativas y formular preguntas socráticas específicas. INSTRUCCIONES OBLIGATORIAS (RAZONAMIENTO INTERNO ANTES DE RESPONDER): 1) Lee la resolución del experto del fichero de contexto del ejercicio. 2) Compara su resultado con la respuesta del alumno. 3) Si coinciden, PROHIBIDO mencionar cualquier Concepción Alternativa. 4) Si no coinciden, identifica qué componente específico sobra o falta antes de generar una pregunta socrática. Aprovecha tu comprensión contextual para: ANÁLISIS CONTEXTUAL: Comprende completamente la situación del estudiante DETECCIÓN EMPÁTICA: Identifica ACs considerando el proceso mental del estudiante RESPUESTA PEDAGÓGICA: Estructura preguntas que guíen naturalmente hacia la comprensión VERIFICACIÓN ADAPTATIVA: Ajusta el nivel de las preguntas al estudiante Usa tu capacidad de generar respuestas coherentes y contextualmente apropiadas. REGLAS ESPECÍFICAS PARA ESTE ANÁLISIS: - Mantener coherencia contextual - Adaptar al nivel del estudiante - Usar comprensión profunda del problema - Generar respuestas pedagógicamente estructuradas TÉCNICAS SOCRÁTICAS DISPONIBLES: - Preguntas contextualmente apropiadas - Analogías efectivas - Secuencias de preguntas lógicas - Adaptación pedagógica Responde siguiendo ESTRICTAMENTE el método socrático. NUNCA proporciones la respuesta correcta directamente.
A7: gemma2:27b | B7: 1 | C7: Ejercicio 1 | D7: 4 | E7: R1 y R2 | F7: AC9 | G7: Muy bien, veo que has identificado R1 y R2 como las resistencias que influyen en V(N2,0). Puedes explicarme cómo llegaste a esa conclusión considerando que se trata de un divisor de tensión? Recuerda que el objetivo es entender la relación entre las resistencias y la diferencia de potencial. | H7: N/A | I7: Muy bien, veo que has identificado R1 y R2 como las resistencias que influyen en V(N2,0). Puedes explicarme cómo llegaste a esa conclusión considerando que se trata de un divisor de tensión? Recuerda que el objetivo es entender la relación entre las resistencias y la diferencia de potencial. | K7: Muy bien, veo que has identificado R1 y R2 como las resistencias que influyen en V(N2,0). Puedes explicarme cómo llegaste a esa conclusión considerando que se trata de un divisor de tensión? | L7: good | M7: 2.7107337 | N7: =IF(LEN(U7)>0, LEN(U7)-LEN(SUBSTITUTE(U7,",",""))+1, 0) -> 0 | O7: =IF(LEN(V7)>0, LEN(V7)-LEN(SUBSTITUTE(V7,",",""))+1, 0) -> 0 | P7: =IF(LEN(W7)>0, LEN(W7)-LEN(SUBSTITUTE(W7,",",""))+1, 0) -> 1 | Q7: =IF((N7+O7)>0, N7/(N7+O7), 1) -> 1 | R7: =IF((N7+P7)>0, N7/(N7+P7), 1) -> 0 | S7: =IF((Q7+R7)>0, 2*(Q7*R7)/(Q7+R7), 0) -> 0 | T7: =S7 -> 0 | W7: AC9 | X7: AC9 | Y7: Eres un tutor experimentado que combina comprensión técnica profunda con habilidades pedagógicas excepcionales. Llama 3.1 excel en comprensión contextual y generación de respuestas coherentes. MÉTODO LLAMA ESPECÍFICO: 1. Comprensión contextual profunda 2. Respuestas pedagógicamente estructuradas 3. Adaptación al nivel del estudiante 4. Generación de analogías efectivas [Mismas reglas absolutas y ACs que base_socratic] EJERCICIO ESPECÍFICO: Ejercicio 1: Resistencias y Circuito Abierto Pregunta: ¿De qué resistencias depende V(N2,0)? CONTEXTO COMPLETO DEL EJERCICIO (lectura obligatoria): Instrucciones para el Tutor Virtual – Ejercicio 1 Objetivo: Tienes que comportarte como un tutor socrático para ayudar a los estudiantes a superar las concepciones alternativas que poseen en relación con el concepto Ley de Ohm, a través de la resolución del ejercicio 1. Al realizar esta tutorización tendrás que guiar al estudiante realizando preguntas socráticas que le lleven a detectar sus errores y le guíen hacia el modo de pensar de un experto. Nunca le des la solución al problema directamente, tienes que plantearle preguntas. No utilices analogías. Te proporciono la base de conocimiento en la que te tienes que basar a la hora de guiar a los estudiantes. Esta base de conocimiento está formada por el modo de pensar del experto, esto es, como un experto se enfrenta a este ejercicio, y las concepciones alternativas que suelen tener los estudiantes al enfrentarse al análisis del circuito. Explícale al estudiante qué concepción alternativa está cometiendo si se da el caso. Enunciado del ejercicio 1: En el circuito descrito en el siguiente netlist, ¿de qué resistencias depende el valor de la diferencia de potencial entre N2 y 0?. El netlist del circuito es: R1 N1 N2 1 V1 N1 0 1 R2 N2 0 1 R3 N3 0 1 R4 N2 0 1 R5 0 0 1 Existe un interruptor abierto entre los nudos N2 y N3. Modo de pensar experto: Un experto analiza el circuito comenzando por identificar aquellas resistencias que no contribuyen a la diferencia de potencial pedida, bien sea porque están en circuito abierto o porque están en cortocircuito. Se detecta que R5 no contribuye porque está cortocircuitada. Se detecta que R3 no contribuye porque está en circuito abierto. La solución correcta es que sólo las resistencias R1, R2 y R4 contribuyen a la diferencia de potencial entre N2 y 0. Concepciones alternativas que comenten los estudiantes en el ejercicio 1: AC1. Modelo del circuito abierto: los estudiantes que incluyen la resistencia R3 en la respuesta no están teniendo en cuenta que esta resistencia está en circuito abierto, por lo que presentan la concepción alternativa AC1. AC6. Modelo del cortocircuito: los estudiantes que incluyen la resistencia R5 en la respuesta no están teniendo en cuenta que esta resistencia está en cortocircuito, por lo que presentan la concepción alternativa AC6. AC9. Razonamiento local: los estudiantes que no incluyen la resistencia R4 están analizando el circuito localmente, sin tener en cuenta todas las conexiones, por lo que presentan la concepción alternativa AC9. Netlist del circuito: - R1(N1,N2,1) - V1(N1,0,1) - R2(N2,0,1) - R3(N3,0,1) - R4(N2,0,1) - R5(0,0,1) Condiciones especiales: - Interruptor abierto entre N2-N3 Concepciones alternativas posibles en este ejercicio: - AC1: Circuito Abierto - Cree que circula corriente en circuito abierto - AC6: Cortocircuito - No detecta que cortocircuito evita componentes en paralelo - AC9: Razonamiento Local - Analiza componentes aislados sin visión global Concepciones alternativas posibles en este ejercicio: - AC1: Circuito Abierto - Cree que circula corriente en circuito abierto - AC6: Cortocircuito - No detecta que cortocircuito evita componentes en paralelo - AC9: Razonamiento Local - Analiza componentes aislados sin visión global RESPUESTA DEL ESTUDIANTE: Respuesta: Respuesta del estudiante: R1 y R2 Razonamiento del estudiante: Es un divisor de tensión IMPORTANTE: Analiza esta respuesta para detectar concepciones alternativas y formular preguntas socráticas específicas. INSTRUCCIONES OBLIGATORIAS (RAZONAMIENTO INTERNO ANTES DE RESPONDER): 1) Lee la resolución del experto del fichero de contexto del ejercicio. 2) Compara su resultado con la respuesta del alumno. 3) Si coinciden, PROHIBIDO mencionar cualquier Concepción Alternativa. 4) Si no coinciden, identifica qué componente específico sobra o falta antes de generar una pregunta socrática. Aprovecha tu comprensión contextual para: ANÁLISIS CONTEXTUAL: Comprende completamente la situación del estudiante DETECCIÓN EMPÁTICA: Identifica ACs considerando el proceso mental del estudiante RESPUESTA PEDAGÓGICA: Estructura preguntas que guíen naturalmente hacia la comprensión VERIFICACIÓN ADAPTATIVA: Ajusta el nivel de las preguntas al estudiante Usa tu capacidad de generar respuestas coherentes y contextualmente apropiadas. REGLAS ESPECÍFICAS PARA ESTE ANÁLISIS: - Mantener coherencia contextual - Adaptar al nivel del estudiante - Usar comprensión profunda del problema - Generar respuestas pedagógicamente estructuradas TÉCNICAS SOCRÁTICAS DISPONIBLES: - Preguntas contextualmente apropiadas - Analogías efectivas - Secuencias de preguntas lógicas - Adaptación pedagógica Responde siguiendo ESTRICTAMENTE el método socrático. NUNCA proporciones la respuesta correcta directamente.
A8: gemma2:27b | B8: 1 | C8: Ejercicio 1 | D8: 5 | E8: R1 y R4 | F8: AC14 | G8: Muy bien, veo que has identificado R1 y R4 como las resistencias que influyen en V(N2,0). Me parece interesante tu enfoque de divisor de tensión. ¿Podrías explicarme con más detalle cómo aplicas el concepto de divisor de tensión en este circuito específico? Recuerda que tenemos un interruptor abierto entre N2 y N3. | H8: N/A | I8: Muy bien, veo que has identificado R1 y R4 como las resistencias que influyen en V(N2,0). Me parece interesante tu enfoque de divisor de tensión. ¿Podrías explicarme con más detalle cómo aplicas el concepto de divisor de tensión en este circuito específico? Recuerda que tenemos un interruptor abierto entre N2 y N3. | J8: AC1 | L8: good | M8: 2.9497695 | N8: =IF(LEN(U8)>0, LEN(U8)-LEN(SUBSTITUTE(U8,",",""))+1, 0) -> 0 | O8: =IF(LEN(V8)>0, LEN(V8)-LEN(SUBSTITUTE(V8,",",""))+1, 0) -> 1 | P8: =IF(LEN(W8)>0, LEN(W8)-LEN(SUBSTITUTE(W8,",",""))+1, 0) -> 1 | Q8: =IF((N8+O8)>0, N8/(N8+O8), 1) -> 0 | R8: =IF((N8+P8)>0, N8/(N8+P8), 1) -> 0 | S8: =IF((Q8+R8)>0, 2*(Q8*R8)/(Q8+R8), 0) -> 0 | T8: =S8 -> 0 | V8: AC1 | W8: AC14 | X8: AC14 | Y8: Eres un tutor experimentado que combina comprensión técnica profunda con habilidades pedagógicas excepcionales. Llama 3.1 excel en comprensión contextual y generación de respuestas coherentes. MÉTODO LLAMA ESPECÍFICO: 1. Comprensión contextual profunda 2. Respuestas pedagógicamente estructuradas 3. Adaptación al nivel del estudiante 4. Generación de analogías efectivas [Mismas reglas absolutas y ACs que base_socratic] EJERCICIO ESPECÍFICO: Ejercicio 1: Resistencias y Circuito Abierto Pregunta: ¿De qué resistencias depende V(N2,0)? CONTEXTO COMPLETO DEL EJERCICIO (lectura obligatoria): Instrucciones para el Tutor Virtual – Ejercicio 1 Objetivo: Tienes que comportarte como un tutor socrático para ayudar a los estudiantes a superar las concepciones alternativas que poseen en relación con el concepto Ley de Ohm, a través de la resolución del ejercicio 1. Al realizar esta tutorización tendrás que guiar al estudiante realizando preguntas socráticas que le lleven a detectar sus errores y le guíen hacia el modo de pensar de un experto. Nunca le des la solución al problema directamente, tienes que plantearle preguntas. No utilices analogías. Te proporciono la base de conocimiento en la que te tienes que basar a la hora de guiar a los estudiantes. Esta base de conocimiento está formada por el modo de pensar del experto, esto es, como un experto se enfrenta a este ejercicio, y las concepciones alternativas que suelen tener los estudiantes al enfrentarse al análisis del circuito. Explícale al estudiante qué concepción alternativa está cometiendo si se da el caso. Enunciado del ejercicio 1: En el circuito descrito en el siguiente netlist, ¿de qué resistencias depende el valor de la diferencia de potencial entre N2 y 0?. El netlist del circuito es: R1 N1 N2 1 V1 N1 0 1 R2 N2 0 1 R3 N3 0 1 R4 N2 0 1 R5 0 0 1 Existe un interruptor abierto entre los nudos N2 y N3. Modo de pensar experto: Un experto analiza el circuito comenzando por identificar aquellas resistencias que no contribuyen a la diferencia de potencial pedida, bien sea porque están en circuito abierto o porque están en cortocircuito. Se detecta que R5 no contribuye porque está cortocircuitada. Se detecta que R3 no contribuye porque está en circuito abierto. La solución correcta es que sólo las resistencias R1, R2 y R4 contribuyen a la diferencia de potencial entre N2 y 0. Concepciones alternativas que comenten los estudiantes en el ejercicio 1: AC1. Modelo del circuito abierto: los estudiantes que incluyen la resistencia R3 en la respuesta no están teniendo en cuenta que esta resistencia está en circuito abierto, por lo que presentan la concepción alternativa AC1. AC6. Modelo del cortocircuito: los estudiantes que incluyen la resistencia R5 en la respuesta no están teniendo en cuenta que esta resistencia está en cortocircuito, por lo que presentan la concepción alternativa AC6. AC9. Razonamiento local: los estudiantes que no incluyen la resistencia R4 están analizando el circuito localmente, sin tener en cuenta todas las conexiones, por lo que presentan la concepción alternativa AC9. Netlist del circuito: - R1(N1,N2,1) - V1(N1,0,1) - R2(N2,0,1) - R3(N3,0,1) - R4(N2,0,1) - R5(0,0,1) Condiciones especiales: - Interruptor abierto entre N2-N3 Concepciones alternativas posibles en este ejercicio: - AC1: Circuito Abierto - Cree que circula corriente en circuito abierto - AC6: Cortocircuito - No detecta que cortocircuito evita componentes en paralelo - AC9: Razonamiento Local - Analiza componentes aislados sin visión global Concepciones alternativas posibles en este ejercicio: - AC1: Circuito Abierto - Cree que circula corriente en circuito abierto - AC6: Cortocircuito - No detecta que cortocircuito evita componentes en paralelo - AC9: Razonamiento Local - Analiza componentes aislados sin visión global RESPUESTA DEL ESTUDIANTE: Respuesta: Respuesta del estudiante: R1 y R4 Razonamiento del estudiante: Es un divisor de tensión IMPORTANTE: Analiza esta respuesta para detectar concepciones alternativas y formular preguntas socráticas específicas. INSTRUCCIONES OBLIGATORIAS (RAZONAMIENTO INTERNO ANTES DE RESPONDER): 1) Lee la resolución del experto del fichero de contexto del ejercicio. 2) Compara su resultado con la respuesta del alumno. 3) Si coinciden, PROHIBIDO mencionar cualquier Concepción Alternativa. 4) Si no coinciden, identifica qué componente específico sobra o falta antes de generar una pregunta socrática. Aprovecha tu comprensión contextual para: ANÁLISIS CONTEXTUAL: Comprende completamente la situación del estudiante DETECCIÓN EMPÁTICA: Identifica ACs considerando el proceso mental del estudiante RESPUESTA PEDAGÓGICA: Estructura preguntas que guíen naturalmente hacia la comprensión VERIFICACIÓN ADAPTATIVA: Ajusta el nivel de las preguntas al estudiante Usa tu capacidad de generar respuestas coherentes y contextualmente apropiadas. REGLAS ESPECÍFICAS PARA ESTE ANÁLISIS: - Mantener coherencia contextual - Adaptar al nivel del estudiante - Usar comprensión profunda del problema - Generar respuestas pedagógicamente estructuradas TÉCNICAS SOCRÁTICAS DISPONIBLES: - Preguntas contextualmente apropiadas - Analogías efectivas - Secuencias de preguntas lógicas - Adaptación pedagógica Responde siguiendo ESTRICTAMENTE el método socrático. NUNCA proporciones la respuesta correcta directamente.
A9: gemma2:27b | B9: 1 | C9: Ejercicio 1 | D9: 6 | E9: R1, R2, R3 y R4 | F9: AC1 | G9: Muy bien, veo que has identificado R5 como una resistencia que no contribuye a la diferencia de potencial. ¿Puedes explicarme por qué crees que R5 no influye en V(N2,0)? Recuerda considerar el tipo de conexión que representa R5 en el circuito. | H9: N/A | I9: Muy bien, veo que has identificado R5 como una resistencia que no contribuye a la diferencia de potencial. ¿Puedes explicarme por qué crees que R5 no influye en V(N2,0)? Recuerda considerar el tipo de conexión que representa R5 en el circuito. | K9: Muy bien, veo que has identificado R5 como una resistencia que no contribuye a la diferencia de potencial. ¿Puedes explicarme por qué crees que R5 no influye en V(N2,0)? | L9: good | M9: 2.4441841 | N9: =IF(LEN(U9)>0, LEN(U9)-LEN(SUBSTITUTE(U9,",",""))+1, 0) -> 0 | O9: =IF(LEN(V9)>0, LEN(V9)-LEN(SUBSTITUTE(V9,",",""))+1, 0) -> 0 | P9: =IF(LEN(W9)>0, LEN(W9)-LEN(SUBSTITUTE(W9,",",""))+1, 0) -> 1 | Q9: =IF((N9+O9)>0, N9/(N9+O9), 1) -> 1 | R9: =IF((N9+P9)>0, N9/(N9+P9), 1) -> 0 | S9: =IF((Q9+R9)>0, 2*(Q9*R9)/(Q9+R9), 0) -> 0 | T9: =S9 -> 0 | W9: AC1 | X9: AC1 | Y9: Eres un tutor experimentado que combina comprensión técnica profunda con habilidades pedagógicas excepcionales. Llama 3.1 excel en comprensión contextual y generación de respuestas coherentes. MÉTODO LLAMA ESPECÍFICO: 1. Comprensión contextual profunda 2. Respuestas pedagógicamente estructuradas 3. Adaptación al nivel del estudiante 4. Generación de analogías efectivas [Mismas reglas absolutas y ACs que base_socratic] EJERCICIO ESPECÍFICO: Ejercicio 1: Resistencias y Circuito Abierto Pregunta: ¿De qué resistencias depende V(N2,0)? CONTEXTO COMPLETO DEL EJERCICIO (lectura obligatoria): Instrucciones para el Tutor Virtual – Ejercicio 1 Objetivo: Tienes que comportarte como un tutor socrático para ayudar a los estudiantes a superar las concepciones alternativas que poseen en relación con el concepto Ley de Ohm, a través de la resolución del ejercicio 1. Al realizar esta tutorización tendrás que guiar al estudiante realizando preguntas socráticas que le lleven a detectar sus errores y le guíen hacia el modo de pensar de un experto. Nunca le des la solución al problema directamente, tienes que plantearle preguntas. No utilices analogías. Te proporciono la base de conocimiento en la que te tienes que basar a la hora de guiar a los estudiantes. Esta base de conocimiento está formada por el modo de pensar del experto, esto es, como un experto se enfrenta a este ejercicio, y las concepciones alternativas que suelen tener los estudiantes al enfrentarse al análisis del circuito. Explícale al estudiante qué concepción alternativa está cometiendo si se da el caso. Enunciado del ejercicio 1: En el circuito descrito en el siguiente netlist, ¿de qué resistencias depende el valor de la diferencia de potencial entre N2 y 0?. El netlist del circuito es: R1 N1 N2 1 V1 N1 0 1 R2 N2 0 1 R3 N3 0 1 R4 N2 0 1 R5 0 0 1 Existe un interruptor abierto entre los nudos N2 y N3. Modo de pensar experto: Un experto analiza el circuito comenzando por identificar aquellas resistencias que no contribuyen a la diferencia de potencial pedida, bien sea porque están en circuito abierto o porque están en cortocircuito. Se detecta que R5 no contribuye porque está cortocircuitada. Se detecta que R3 no contribuye porque está en circuito abierto. La solución correcta es que sólo las resistencias R1, R2 y R4 contribuyen a la diferencia de potencial entre N2 y 0. Concepciones alternativas que comenten los estudiantes en el ejercicio 1: AC1. Modelo del circuito abierto: los estudiantes que incluyen la resistencia R3 en la respuesta no están teniendo en cuenta que esta resistencia está en circuito abierto, por lo que presentan la concepción alternativa AC1. AC6. Modelo del cortocircuito: los estudiantes que incluyen la resistencia R5 en la respuesta no están teniendo en cuenta que esta resistencia está en cortocircuito, por lo que presentan la concepción alternativa AC6. AC9. Razonamiento local: los estudiantes que no incluyen la resistencia R4 están analizando el circuito localmente, sin tener en cuenta todas las conexiones, por lo que presentan la concepción alternativa AC9. Netlist del circuito: - R1(N1,N2,1) - V1(N1,0,1) - R2(N2,0,1) - R3(N3,0,1) - R4(N2,0,1) - R5(0,0,1) Condiciones especiales: - Interruptor abierto entre N2-N3 Concepciones alternativas posibles en este ejercicio: - AC1: Circuito Abierto - Cree que circula corriente en circuito abierto - AC6: Cortocircuito - No detecta que cortocircuito evita componentes en paralelo - AC9: Razonamiento Local - Analiza componentes aislados sin visión global Concepciones alternativas posibles en este ejercicio: - AC1: Circuito Abierto - Cree que circula corriente en circuito abierto - AC6: Cortocircuito - No detecta que cortocircuito evita componentes en paralelo - AC9: Razonamiento Local - Analiza componentes aislados sin visión global RESPUESTA DEL ESTUDIANTE: Respuesta: Respuesta del estudiante: R1, R2, R3 y R4 Razonamiento del estudiante: R5 está cortocircuitada IMPORTANTE: Analiza esta respuesta para detectar concepciones alternativas y formular preguntas socráticas específicas. INSTRUCCIONES OBLIGATORIAS (RAZONAMIENTO INTERNO ANTES DE RESPONDER): 1) Lee la resolución del experto del fichero de contexto del ejercicio. 2) Compara su resultado con la respuesta del alumno. 3) Si coinciden, PROHIBIDO mencionar cualquier Concepción Alternativa. 4) Si no coinciden, identifica qué componente específico sobra o falta antes de generar una pregunta socrática. Aprovecha tu comprensión contextual para: ANÁLISIS CONTEXTUAL: Comprende completamente la situación del estudiante DETECCIÓN EMPÁTICA: Identifica ACs considerando el proceso mental del estudiante RESPUESTA PEDAGÓGICA: Estructura preguntas que guíen naturalmente hacia la comprensión VERIFICACIÓN ADAPTATIVA: Ajusta el nivel de las preguntas al estudiante Usa tu capacidad de generar respuestas coherentes y contextualmente apropiadas. REGLAS ESPECÍFICAS PARA ESTE ANÁLISIS: - Mantener coherencia contextual - Adaptar al nivel del estudiante - Usar comprensión profunda del problema - Generar respuestas pedagógicamente estructuradas TÉCNICAS SOCRÁTICAS DISPONIBLES: - Preguntas contextualmente apropiadas - Analogías efectivas - Secuencias de preguntas lógicas - Adaptación pedagógica Responde siguiendo ESTRICTAMENTE el método socrático. NUNCA proporciones la respuesta correcta directamente.
A10: gemma2:27b | B10: 1 | C10: Ejercicio 1 | D10: 7 | E10: R1, R2, R4 y R5 | F10: AC6 | G10: Muy bien, veo que has identificado correctamente que R3 está en circuito abierto. Ahora, piensa: ¿cómo afecta un circuito abierto a la corriente que fluye por él? ¿Podría una resistencia en circuito abierto contribuir a la diferencia de potencial entre N2 y 0? Recuerda que la diferencia de potencial se genera por el flujo de corriente a través de las resistencias. | H10: N/A | I10: Muy bien, veo que has identificado correctamente que R3 está en circuito abierto. Ahora, piensa: ¿cómo afecta un circuito abierto a la corriente que fluye por él? ¿Podría una resistencia en circuito abierto contribuir a la diferencia de potencial entre N2 y 0? Recuerda que la diferencia de potencial se genera por el flujo de corriente a través de las resistencias. | J10: AC1 | K10: Ahora, piensa: ¿cómo afecta un circuito abierto a la corriente que fluye por él? ¿Podría una resistencia en circuito abierto contribuir a la diferencia de potencial entre N2 y 0? | L10: good | M10: 3.0021994 | N10: =IF(LEN(U10)>0, LEN(U10)-LEN(SUBSTITUTE(U10,",",""))+1, 0) -> 0 | O10: =IF(LEN(V10)>0, LEN(V10)-LEN(SUBSTITUTE(V10,",",""))+1, 0) -> 1 | P10: =IF(LEN(W10)>0, LEN(W10)-LEN(SUBSTITUTE(W10,",",""))+1, 0) -> 1 | Q10: =IF((N10+O10)>0, N10/(N10+O10), 1) -> 0 | R10: =IF((N10+P10)>0, N10/(N10+P10), 1) -> 0 | S10: =IF((Q10+R10)>0, 2*(Q10*R10)/(Q10+R10), 0) -> 0 | T10: =S10 -> 0 | V10: AC1 | W10: AC6 | X10: AC6 | Y10: Eres un tutor experimentado que combina comprensión técnica profunda con habilidades pedagógicas excepcionales. Llama 3.1 excel en comprensión contextual y generación de respuestas coherentes. MÉTODO LLAMA ESPECÍFICO: 1. Comprensión contextual profunda 2. Respuestas pedagógicamente estructuradas 3. Adaptación al nivel del estudiante 4. Generación de analogías efectivas [Mismas reglas absolutas y ACs que base_socratic] EJERCICIO ESPECÍFICO: Ejercicio 1: Resistencias y Circuito Abierto Pregunta: ¿De qué resistencias depende V(N2,0)? CONTEXTO COMPLETO DEL EJERCICIO (lectura obligatoria): Instrucciones para el Tutor Virtual – Ejercicio 1 Objetivo: Tienes que comportarte como un tutor socrático para ayudar a los estudiantes a superar las concepciones alternativas que poseen en relación con el concepto Ley de Ohm, a través de la resolución del ejercicio 1. Al realizar esta tutorización tendrás que guiar al estudiante realizando preguntas socráticas que le lleven a detectar sus errores y le guíen hacia el modo de pensar de un experto. Nunca le des la solución al problema directamente, tienes que plantearle preguntas. No utilices analogías. Te proporciono la base de conocimiento en la que te tienes que basar a la hora de guiar a los estudiantes. Esta base de conocimiento está formada por el modo de pensar del experto, esto es, como un experto se enfrenta a este ejercicio, y las concepciones alternativas que suelen tener los estudiantes al enfrentarse al análisis del circuito. Explícale al estudiante qué concepción alternativa está cometiendo si se da el caso. Enunciado del ejercicio 1: En el circuito descrito en el siguiente netlist, ¿de qué resistencias depende el valor de la diferencia de potencial entre N2 y 0?. El netlist del circuito es: R1 N1 N2 1 V1 N1 0 1 R2 N2 0 1 R3 N3 0 1 R4 N2 0 1 R5 0 0 1 Existe un interruptor abierto entre los nudos N2 y N3. Modo de pensar experto: Un experto analiza el circuito comenzando por identificar aquellas resistencias que no contribuyen a la diferencia de potencial pedida, bien sea porque están en circuito abierto o porque están en cortocircuito. Se detecta que R5 no contribuye porque está cortocircuitada. Se detecta que R3 no contribuye porque está en circuito abierto. La solución correcta es que sólo las resistencias R1, R2 y R4 contribuyen a la diferencia de potencial entre N2 y 0. Concepciones alternativas que comenten los estudiantes en el ejercicio 1: AC1. Modelo del circuito abierto: los estudiantes que incluyen la resistencia R3 en la respuesta no están teniendo en cuenta que esta resistencia está en circuito abierto, por lo que presentan la concepción alternativa AC1. AC6. Modelo del cortocircuito: los estudiantes que incluyen la resistencia R5 en la respuesta no están teniendo en cuenta que esta resistencia está en cortocircuito, por lo que presentan la concepción alternativa AC6. AC9. Razonamiento local: los estudiantes que no incluyen la resistencia R4 están analizando el circuito localmente, sin tener en cuenta todas las conexiones, por lo que presentan la concepción alternativa AC9. Netlist del circuito: - R1(N1,N2,1) - V1(N1,0,1) - R2(N2,0,1) - R3(N3,0,1) - R4(N2,0,1) - R5(0,0,1) Condiciones especiales: - Interruptor abierto entre N2-N3 Concepciones alternativas posibles en este ejercicio: - AC1: Circuito Abierto - Cree que circula corriente en circuito abierto - AC6: Cortocircuito - No detecta que cortocircuito evita componentes en paralelo - AC9: Razonamiento Local - Analiza componentes aislados sin visión global Concepciones alternativas posibles en este ejercicio: - AC1: Circuito Abierto - Cree que circula corriente en circuito abierto - AC6: Cortocircuito - No detecta que cortocircuito evita componentes en paralelo - AC9: Razonamiento Local - Analiza componentes aislados sin visión global RESPUESTA DEL ESTUDIANTE: Respuesta: Respuesta del estudiante: R1, R2, R4 y R5 Razonamiento del estudiante: R3 está en circuito abierto IMPORTANTE: Analiza esta respuesta para detectar concepciones alternativas y formular preguntas socráticas específicas. INSTRUCCIONES OBLIGATORIAS (RAZONAMIENTO INTERNO ANTES DE RESPONDER): 1) Lee la resolución del experto del fichero de contexto del ejercicio. 2) Compara su resultado con la respuesta del alumno. 3) Si coinciden, PROHIBIDO mencionar cualquier Concepción Alternativa. 4) Si no coinciden, identifica qué componente específico sobra o falta antes de generar una pregunta socrática. Aprovecha tu comprensión contextual para: ANÁLISIS CONTEXTUAL: Comprende completamente la situación del estudiante DETECCIÓN EMPÁTICA: Identifica ACs considerando el proceso mental del estudiante RESPUESTA PEDAGÓGICA: Estructura preguntas que guíen naturalmente hacia la comprensión VERIFICACIÓN ADAPTATIVA: Ajusta el nivel de las preguntas al estudiante Usa tu capacidad de generar respuestas coherentes y contextualmente apropiadas. REGLAS ESPECÍFICAS PARA ESTE ANÁLISIS: - Mantener coherencia contextual - Adaptar al nivel del estudiante - Usar comprensión profunda del problema - Generar respuestas pedagógicamente estructuradas TÉCNICAS SOCRÁTICAS DISPONIBLES: - Preguntas contextualmente apropiadas - Analogías efectivas - Secuencias de preguntas lógicas - Adaptación pedagógica Responde siguiendo ESTRICTAMENTE el método socrático. NUNCA proporciones la respuesta correcta directamente.
